Workbook
Name Cat_DF_Abonnements: Données!$H$2:$H$10
Name Cat_DF_Epargne: Données!$I$2:$I$10
Name Cat_DF_Logement: Données!$F$2:$F$10
Name Cat_DF_Obligations: Données!$J$2:$J$10
Name Cat_DF_Transport: Données!$G$2:$G$10
Name Cat_DV_Autres: Données!$N$2:$N$3
Name Cat_DV_Loisirs: Données!$M$2:$M$10
Name Cat_DV_Transport: Données!$L$2:$L$10
Name Cat_DV_VieQuotidienne: Données!$K$2:$K$10
Name Cat_Revenus: Données!$E$2:$E$10
Name CategoryList: Données!$C$1:$C$66
Name Historique_Categorie: Historique!$C$7:$C$9999
Name Historique_Commentaires: Historique!$H$7:$H$9999
Name Historique_Date: Historique!$G$7:$G$9999
Name Historique_Enregistre: Historique!$F$7:$F$9999
Name Historique_Mois: Historique!$A$7:$A$9999
Name Historique_Montant: Historique!$E$7:$E$9999
Name Historique_Section: Historique!$B$7:$B$9999
Name Historique_Statut: Historique!$D$7:$D$9999
Name MonthList: Données!$A$1:$A$13
Name SectionList: Données!$B$1:$B$11

Sheet Budget_mensuel
A1: Budget mensuel - Planification mensuel pour jeune adulte -
A6: R E V E N U S
B7: Janvier | C7: Février | D7: Mars | E7: Avril | F7: Mai | G7: Juin | H7: Juillet | I7: Août | J7: Septembre | K7: Octobre | L7: Novembre | M7: Décembre | N7: TOTAL ANNUEL
A8: Salaire et retraite | B8: =SUMIFS( Historique_Montant, Historique_Mois,B$7, Historique_Section,"Revenus", Historique_Categorie,$A8, Historique_Enregistre,TRUE, Historique_Statut,"OK" ) -> 1800 | C8: =SUMIFS( Historique_Montant, Historique_Mois,C$7, Historique_Section,"Revenus", Historique_Categorie,$A8, Historique_Enregistre,TRUE, Historique_Statut,"OK" ) -> 0 | D8: =SUMIFS( Historique_Montant, Historique_Mois,D$7, Historique_Section,"Revenus", Historique_Categorie,$A8, Historique_Enregistre,TRUE, Historique_Statut,"OK" ) -> 0 | E8: =SUMIFS( Historique_Montant, Historique_Mois,E$7, Historique_Section,"Revenus", Historique_Categorie,$A8, Historique_Enregistre,TRUE, Historique_Statut,"OK" ) -> 0 | F8: =SUMIFS( Historique_Montant, Historique_Mois,F$7, Historique_Section,"Revenus", Historique_Categorie,$A8, Historique_Enregistre,TRUE, Historique_Statut,"OK" ) -> 0 | G8: =SUMIFS( Historique_Montant, Historique_Mois,G$7, Historique_Section,"Revenus", Historique_Categorie,$A8, Historique_Enregistre,TRUE, Historique_Statut,"OK" ) -> 0 | H8: =SUMIFS( Historique_Montant, Historique_Mois,H$7, Historique_Section,"Revenus", Historique_Categorie,$A8, Historique_Enregistre,TRUE, Historique_Statut,"OK" ) -> 0 | I8: =SUMIFS( Historique_Montant, Historique_Mois,I$7, Historique_Section,"Revenus", Historique_Categorie,$A8, Historique_Enregistre,TRUE, Historique_Statut,"OK" ) -> 0 | ... M8: =SUMIFS( Historique_Montant, Historique_Mois,M$7, Historique_Section,"Revenus", Historique_Categorie,$A8, Historique_Enregistre,TRUE, Historique_Statut,"OK" ) -> 0 | N8: =SUM(B8:M8) -> 1800
A9: Allocations et prestations sociales | B9: =SUMIFS( Historique_Montant, Historique_Mois,B$7, Historique_Section,"Revenus", Historique_Categorie,$A9, Historique_Enregistre,TRUE, Historique_Statut,"OK" ) -> 0 | C9: =SUMIFS( Historique_Montant, Historique_Mois,C$7, Historique_Section,"Revenus", Historique_Categorie,$A9, Historique_Enregistre,TRUE, Historique_Statut,"OK" ) -> 0 | D9: =SUMIFS( Historique_Montant, Historique_Mois,D$7, Historique_Section,"Revenus", Historique_Categorie,$A9, Historique_Enregistre,TRUE, Historique_Statut,"OK" ) -> 0 | E9: =SUMIFS( Historique_Montant, Historique_Mois,E$7, Historique_Section,"Revenus", Historique_Categorie,$A9, Historique_Enregistre,TRUE, Historique_Statut,"OK" ) -> 0 | F9: =SUMIFS( Historique_Montant, Historique_Mois,F$7, Historique_Section,"Revenus", Historique_Categorie,$A9, Historique_Enregistre,TRUE, Historique_Statut,"OK" ) -> 0 | G9: =SUMIFS( Historique_Montant, Historique_Mois,G$7, Historique_Section,"Revenus", Historique_Categorie,$A9, Historique_Enregistre,TRUE, Historique_Statut,"OK" ) -> 0 | H9: =SUMIFS( Historique_Montant, Historique_Mois,H$7, Historique_Section,"Revenus", Historique_Categorie,$A9, Historique_Enregistre,TRUE, Historique_Statut,"OK" ) -> 0 | I9: =SUMIFS( Historique_Montant, Historique_Mois,I$7, Historique_Section,"Revenus", Historique_Categorie,$A9, Historique_Enregistre,TRUE, Historique_Statut,"OK" ) -> 0 | ... M9: =SUMIFS( Historique_Montant, Historique_Mois,M$7, Historique_Section,"Revenus", Historique_Categorie,$A9, Historique_Enregistre,TRUE, Historique_Statut,"OK" ) -> 0 | N9: =SUM(B9:M9) -> 0
A10: Loyers | B10: =SUMIFS( Historique_Montant, Historique_Mois,B$7, Historique_Section,"Revenus", Historique_Categorie,$A10, Historique_Enregistre,TRUE, Historique_Statut,"OK" ) -> 0 | C10: =SUMIFS( Historique_Montant, Historique_Mois,C$7, Historique_Section,"Revenus", Historique_Categorie,$A10, Historique_Enregistre,TRUE, Historique_Statut,"OK" ) -> 0 | D10: =SUMIFS( Historique_Montant, Historique_Mois,D$7, Historique_Section,"Revenus", Historique_Categorie,$A10, Historique_Enregistre,TRUE, Historique_Statut,"OK" ) -> 0 | E10: =SUMIFS( Historique_Montant, Historique_Mois,E$7, Historique_Section,"Revenus", Historique_Categorie,$A10, Historique_Enregistre,TRUE, Historique_Statut,"OK" ) -> 0 | F10: =SUMIFS( Historique_Montant, Historique_Mois,F$7, Historique_Section,"Revenus", Historique_Categorie,$A10, Historique_Enregistre,TRUE, Historique_Statut,"OK" ) -> 0 | G10: =SUMIFS( Historique_Montant, Historique_Mois,G$7, Historique_Section,"Revenus", Historique_Categorie,$A10, Historique_Enregistre,TRUE, Historique_Statut,"OK" ) -> 0 | H10: =SUMIFS( Historique_Montant, Historique_Mois,H$7, Historique_Section,"Revenus", Historique_Categorie,$A10, Historique_Enregistre,TRUE, Historique_Statut,"OK" ) -> 0 | I10: =SUMIFS( Historique_Montant, Historique_Mois,I$7, Historique_Section,"Revenus", Historique_Categorie,$A10, Historique_Enregistre,TRUE, Historique_Statut,"OK" ) -> 0 | ... M10: =SUMIFS( Historique_Montant, Historique_Mois,M$7, Historique_Section,"Revenus", Historique_Categorie,$A10, Historique_Enregistre,TRUE, Historique_Statut,"OK" ) -> 0 | N10: =SUM(B10:M10) -> 0
A11: Remboursements et virements | B11: =SUMIFS( Historique_Montant, Historique_Mois,B$7, Historique_Section,"Revenus", Historique_Categorie,$A11, Historique_Enregistre,TRUE, Historique_Statut,"OK" ) -> 0 | C11: =SUMIFS( Historique_Montant, Historique_Mois,C$7, Historique_Section,"Revenus", Historique_Categorie,$A11, Historique_Enregistre,TRUE, Historique_Statut,"OK" ) -> 0 | D11: =SUMIFS( Historique_Montant, Historique_Mois,D$7, Historique_Section,"Revenus", Historique_Categorie,$A11, Historique_Enregistre,TRUE, Historique_Statut,"OK" ) -> 0 | E11: =SUMIFS( Historique_Montant, Historique_Mois,E$7, Historique_Section,"Revenus", Historique_Categorie,$A11, Historique_Enregistre,TRUE, Historique_Statut,"OK" ) -> 0 | F11: =SUMIFS( Historique_Montant, Historique_Mois,F$7, Historique_Section,"Revenus", Historique_Categorie,$A11, Historique_Enregistre,TRUE, Historique_Statut,"OK" ) -> 0 | G11: =SUMIFS( Historique_Montant, Historique_Mois,G$7, Historique_Section,"Revenus", Historique_Categorie,$A11, Historique_Enregistre,TRUE, Historique_Statut,"OK" ) -> 0 | H11: =SUMIFS( Historique_Montant, Historique_Mois,H$7, Historique_Section,"Revenus", Historique_Categorie,$A11, Historique_Enregistre,TRUE, Historique_Statut,"OK" ) -> 0 | I11: =SUMIFS( Historique_Montant, Historique_Mois,I$7, Historique_Section,"Revenus", Historique_Categorie,$A11, Historique_Enregistre,TRUE, Historique_Statut,"OK" ) -> 0 | ... M11: =SUMIFS( Historique_Montant, Historique_Mois,M$7, Historique_Section,"Revenus", Historique_Categorie,$A11, Historique_Enregistre,TRUE, Historique_Statut,"OK" ) -> 0 | N11: =SUM(B11:M11) -> 0
A12: Vente d'objets | B12: =SUMIFS( Historique_Montant, Historique_Mois,B$7, Historique_Section,"Revenus", Historique_Categorie,$A12, Historique_Enregistre,TRUE, Historique_Statut,"OK" ) -> 0 | C12: =SUMIFS( Historique_Montant, Historique_Mois,C$7, Historique_Section,"Revenus", Historique_Categorie,$A12, Historique_Enregistre,TRUE, Historique_Statut,"OK" ) -> 0 | D12: =SUMIFS( Historique_Montant, Historique_Mois,D$7, Historique_Section,"Revenus", Historique_Categorie,$A12, Historique_Enregistre,TRUE, Historique_Statut,"OK" ) -> 0 | E12: =SUMIFS( Historique_Montant, Historique_Mois,E$7, Historique_Section,"Revenus", Historique_Categorie,$A12, Historique_Enregistre,TRUE, Historique_Statut,"OK" ) -> 0 | F12: =SUMIFS( Historique_Montant, Historique_Mois,F$7, Historique_Section,"Revenus", Historique_Categorie,$A12, Historique_Enregistre,TRUE, Historique_Statut,"OK" ) -> 0 | G12: =SUMIFS( Historique_Montant, Historique_Mois,G$7, Historique_Section,"Revenus", Historique_Categorie,$A12, Historique_Enregistre,TRUE, Historique_Statut,"OK" ) -> 0 | H12: =SUMIFS( Historique_Montant, Historique_Mois,H$7, Historique_Section,"Revenus", Historique_Categorie,$A12, Historique_Enregistre,TRUE, Historique_Statut,"OK" ) -> 0 | I12: =SUMIFS( Historique_Montant, Historique_Mois,I$7, Historique_Section,"Revenus", Historique_Categorie,$A12, Historique_Enregistre,TRUE, Historique_Statut,"OK" ) -> 0 | ... M12: =SUMIFS( Historique_Montant, Historique_Mois,M$7, Historique_Section,"Revenus", Historique_Categorie,$A12, Historique_Enregistre,TRUE, Historique_Statut,"OK" ) -> 0 | N12: =SUM(B12:M12) -> 0
B13: =SUMIFS( Historique_Montant, Historique_Mois,B$7, Historique_Section,"Revenus", Historique_Categorie,$A13, Historique_Enregistre,TRUE, Historique_Statut,"OK" ) -> 0 | C13: =SUMIFS( Historique_Montant, Historique_Mois,C$7, Historique_Section,"Revenus", Historique_Categorie,$A13, Historique_Enregistre,TRUE, Historique_Statut,"OK" ) -> 0 | D13: =SUMIFS( Historique_Montant, Historique_Mois,D$7, Historique_Section,"Revenus", Historique_Categorie,$A13, Historique_Enregistre,TRUE, Historique_Statut,"OK" ) -> 0 | E13: =SUMIFS( Historique_Montant, Historique_Mois,E$7, Historique_Section,"Revenus", Historique_Categorie,$A13, Historique_Enregistre,TRUE, Historique_Statut,"OK" ) -> 0 | F13: =SUMIFS( Historique_Montant, Historique_Mois,F$7, Historique_Section,"Revenus", Historique_Categorie,$A13, Historique_Enregistre,TRUE, Historique_Statut,"OK" ) -> 0 | G13: =SUMIFS( Historique_Montant, Historique_Mois,G$7, Historique_Section,"Revenus", Historique_Categorie,$A13, Historique_Enregistre,TRUE, Historique_Statut,"OK" ) -> 0 | H13: =SUMIFS( Historique_Montant, Historique_Mois,H$7, Historique_Section,"Revenus", Historique_Categorie,$A13, Historique_Enregistre,TRUE, Historique_Statut,"OK" ) -> 0 | I13: =SUMIFS( Historique_Montant, Historique_Mois,I$7, Historique_Section,"Revenus", Historique_Categorie,$A13, Historique_Enregistre,TRUE, Historique_Statut,"OK" ) -> 0 | ... M13: =SUMIFS( Historique_Montant, Historique_Mois,M$7, Historique_Section,"Revenus", Historique_Categorie,$A13, Historique_Enregistre,TRUE, Historique_Statut,"OK" ) -> 0 | N13: =SUM(B13:M13) -> 0
B14: =SUMIFS( Historique_Montant, Historique_Mois,B$7, Historique_Section,"Revenus", Historique_Categorie,$A14, Historique_Enregistre,TRUE, Historique_Statut,"OK" ) -> 0 | C14: =SUMIFS( Historique_Montant, Historique_Mois,C$7, Historique_Section,"Revenus", Historique_Categorie,$A14, Historique_Enregistre,TRUE, Historique_Statut,"OK" ) -> 0 | D14: =SUMIFS( Historique_Montant, Historique_Mois,D$7, Historique_Section,"Revenus", Historique_Categorie,$A14, Historique_Enregistre,TRUE, Historique_Statut,"OK" ) -> 0 | E14: =SUMIFS( Historique_Montant, Historique_Mois,E$7, Historique_Section,"Revenus", Historique_Categorie,$A14, Historique_Enregistre,TRUE, Historique_Statut,"OK" ) -> 0 | F14: =SUMIFS( Historique_Montant, Historique_Mois,F$7, Historique_Section,"Revenus", Historique_Categorie,$A14, Historique_Enregistre,TRUE, Historique_Statut,"OK" ) -> 0 | G14: =SUMIFS( Historique_Montant, Historique_Mois,G$7, Historique_Section,"Revenus", Historique_Categorie,$A14, Historique_Enregistre,TRUE, Historique_Statut,"OK" ) -> 0 | H14: =SUMIFS( Historique_Montant, Historique_Mois,H$7, Historique_Section,"Revenus", Historique_Categorie,$A14, Historique_Enregistre,TRUE, Historique_Statut,"OK" ) -> 0 | I14: =SUMIFS( Historique_Montant, Historique_Mois,I$7, Historique_Section,"Revenus", Historique_Categorie,$A14, Historique_Enregistre,TRUE, Historique_Statut,"OK" ) -> 0 | ... M14: =SUMIFS( Historique_Montant, Historique_Mois,M$7, Historique_Section,"Revenus", Historique_Categorie,$A14, Historique_Enregistre,TRUE, Historique_Statut,"OK" ) -> 0 | N14: =SUM(B14:M14) -> 0
A15: Autres (revenus) | B15: =SUMIFS( Historique_Montant, Historique_Mois,B$7, Historique_Section,"Revenus", Historique_Categorie,$A15, Historique_Enregistre,TRUE, Historique_Statut,"OK" ) -> 0 | C15: =SUMIFS( Historique_Montant, Historique_Mois,C$7, Historique_Section,"Revenus", Historique_Categorie,$A15, Historique_Enregistre,TRUE, Historique_Statut,"OK" ) -> 0 | D15: =SUMIFS( Historique_Montant, Historique_Mois,D$7, Historique_Section,"Revenus", Historique_Categorie,$A15, Historique_Enregistre,TRUE, Historique_Statut,"OK" ) -> 0 | E15: =SUMIFS( Historique_Montant, Historique_Mois,E$7, Historique_Section,"Revenus", Historique_Categorie,$A15, Historique_Enregistre,TRUE, Historique_Statut,"OK" ) -> 0 | F15: =SUMIFS( Historique_Montant, Historique_Mois,F$7, Historique_Section,"Revenus", Historique_Categorie,$A15, Historique_Enregistre,TRUE, Historique_Statut,"OK" ) -> 0 | G15: =SUMIFS( Historique_Montant, Historique_Mois,G$7, Historique_Section,"Revenus", Historique_Categorie,$A15, Historique_Enregistre,TRUE, Historique_Statut,"OK" ) -> 0 | H15: =SUMIFS( Historique_Montant, Historique_Mois,H$7, Historique_Section,"Revenus", Historique_Categorie,$A15, Historique_Enregistre,TRUE, Historique_Statut,"OK" ) -> 0 | I15: =SUMIFS( Historique_Montant, Historique_Mois,I$7, Historique_Section,"Revenus", Historique_Categorie,$A15, Historique_Enregistre,TRUE, Historique_Statut,"OK" ) -> 0 | ... M15: =SUMIFS( Historique_Montant, Historique_Mois,M$7, Historique_Section,"Revenus", Historique_Categorie,$A15, Historique_Enregistre,TRUE, Historique_Statut,"OK" ) -> 0 | N15: =SUM(B15:M15) -> 0
A16: TOTAL REVENUS | B16: =SUM(SUM(B8:B15)) -> 1800 | C16: =SUM(SUM(C8:C15)) -> 0 | D16: =SUM(SUM(D8:D15)) -> 0 | E16: =SUM(SUM(E8:E15)) -> 0 | F16: =SUM(SUM(F8:F15)) -> 0 | G16: =SUM(SUM(G8:G15)) -> 0 | H16: =SUM(SUM(H8:H15)) -> 0 | I16: =SUM(SUM(I8:I15)) -> 0 | ... M16: =SUM(SUM(M8:M15)) -> 0 | N16: =SUM(B16:M16) -> 1800
A18: D É P E N S E S F I X E S
B19: Janvier | C19: Février | D19: Mars | E19: Avril | F19: Mai | G19: Juin | H19: Juillet | I19: Août | J19: Septembre | K19: Octobre | L19: Novembre | M19: Décembre | N19: TOTAL ANNUEL
A20: Logement | B20: =SUM(B21:B28) -> 0 | C20: =SUM(C21:C28) -> 0 | D20: =SUM(D21:D28) -> 0 | E20: =SUM(E21:E28) -> 0 | F20: =SUM(F21:F28) -> 0 | G20: =SUM(G21:G28) -> 0 | H20: =SUM(H21:H28) -> 0 | I20: =SUM(I21:I28) -> 0 | ... M20: =SUM(M21:M28) -> 0 | N20: =SUM(B20:M20) -> 0
A21: Loyer | B21: =SUMIFS( Historique_Montant, Historique_Mois,B$7, Historique_Section,"Dépenses fixes - "&$A$20, Historique_Categorie,$A21, Historique_Enregistre,TRUE, Historique_Statut,"OK" ) -> 0 | C21: =SUMIFS( Historique_Montant, Historique_Mois,C$7, Historique_Section,"Dépenses fixes - "&$A$20, Historique_Categorie,$A21, Historique_Enregistre,TRUE, Historique_Statut,"OK" ) -> 0 | D21: =SUMIFS( Historique_Montant, Historique_Mois,D$7, Historique_Section,"Dépenses fixes - "&$A$20, Historique_Categorie,$A21, Historique_Enregistre,TRUE, Historique_Statut,"OK" ) -> 0 | E21: =SUMIFS( Historique_Montant, Historique_Mois,E$7, Historique_Section,"Dépenses fixes - "&$A$20, Historique_Categorie,$A21, Historique_Enregistre,TRUE, Historique_Statut,"OK" ) -> 0 | F21: =SUMIFS( Historique_Montant, Historique_Mois,F$7, Historique_Section,"Dépenses fixes - "&$A$20, Historique_Categorie,$A21, Historique_Enregistre,TRUE, Historique_Statut,"OK" ) -> 0 | G21: =SUMIFS( Historique_Montant, Historique_Mois,G$7, Historique_Section,"Dépenses fixes - "&$A$20, Historique_Categorie,$A21, Historique_Enregistre,TRUE, Historique_Statut,"OK" ) -> 0 | H21: =SUMIFS( Historique_Montant, Historique_Mois,H$7, Historique_Section,"Dépenses fixes - "&$A$20, Historique_Categorie,$A21, Historique_Enregistre,TRUE, Historique_Statut,"OK" ) -> 0 | I21: =SUMIFS( Historique_Montant, Historique_Mois,I$7, Historique_Section,"Dépenses fixes - "&$A$20, Historique_Categorie,$A21, Historique_Enregistre,TRUE, Historique_Statut,"OK" ) -> 0 | ... M21: =SUMIFS( Historique_Montant, Historique_Mois,M$7, Historique_Section,"Dépenses fixes - "&$A$20, Historique_Categorie,$A21, Historique_Enregistre,TRUE, Historique_Statut,"OK" ) -> 0 | N21: =SUM(B21:M21) -> 0
A22: Charges de copropriété | B22: =SUMIFS( Historique_Montant, Historique_Mois,B$7, Historique_Section,"Dépenses fixes - "&$A$20, Historique_Categorie,$A22, Historique_Enregistre,TRUE, Historique_Statut,"OK" ) -> 0 | C22: =SUMIFS( Historique_Montant, Historique_Mois,C$7, Historique_Section,"Dépenses fixes - "&$A$20, Historique_Categorie,$A22, Historique_Enregistre,TRUE, Historique_Statut,"OK" ) -> 0 | D22: =SUMIFS( Historique_Montant, Historique_Mois,D$7, Historique_Section,"Dépenses fixes - "&$A$20, Historique_Categorie,$A22, Historique_Enregistre,TRUE, Historique_Statut,"OK" ) -> 0 | E22: =SUMIFS( Historique_Montant, Historique_Mois,E$7, Historique_Section,"Dépenses fixes - "&$A$20, Historique_Categorie,$A22, Historique_Enregistre,TRUE, Historique_Statut,"OK" ) -> 0 | F22: =SUMIFS( Historique_Montant, Historique_Mois,F$7, Historique_Section,"Dépenses fixes - "&$A$20, Historique_Categorie,$A22, Historique_Enregistre,TRUE, Historique_Statut,"OK" ) -> 0 | G22: =SUMIFS( Historique_Montant, Historique_Mois,G$7, Historique_Section,"Dépenses fixes - "&$A$20, Historique_Categorie,$A22, Historique_Enregistre,TRUE, Historique_Statut,"OK" ) -> 0 | H22: =SUMIFS( Historique_Montant, Historique_Mois,H$7, Historique_Section,"Dépenses fixes - "&$A$20, Historique_Categorie,$A22, Historique_Enregistre,TRUE, Historique_Statut,"OK" ) -> 0 | I22: =SUMIFS( Historique_Montant, Historique_Mois,I$7, Historique_Section,"Dépenses fixes - "&$A$20, Historique_Categorie,$A22, Historique_Enregistre,TRUE, Historique_Statut,"OK" ) -> 0 | ... M22: =SUMIFS( Historique_Montant, Historique_Mois,M$7, Historique_Section,"Dépenses fixes - "&$A$20, Historique_Categorie,$A22, Historique_Enregistre,TRUE, Historique_Statut,"OK" ) -> 0 | N22: =SUM(B22:M22) -> 0
A23: Taxe d'habitation, taxe foncière | B23: =SUMIFS( Historique_Montant, Historique_Mois,B$7, Historique_Section,"Dépenses fixes - "&$A$20, Historique_Categorie,$A23, Historique_Enregistre,TRUE, Historique_Statut,"OK" ) -> 0 | C23: =SUMIFS( Historique_Montant, Historique_Mois,C$7, Historique_Section,"Dépenses fixes - "&$A$20, Historique_Categorie,$A23, Historique_Enregistre,TRUE, Historique_Statut,"OK" ) -> 0 | D23: =SUMIFS( Historique_Montant, Historique_Mois,D$7, Historique_Section,"Dépenses fixes - "&$A$20, Historique_Categorie,$A23, Historique_Enregistre,TRUE, Historique_Statut,"OK" ) -> 0 | E23: =SUMIFS( Historique_Montant, Historique_Mois,E$7, Historique_Section,"Dépenses fixes - "&$A$20, Historique_Categorie,$A23, Historique_Enregistre,TRUE, Historique_Statut,"OK" ) -> 0 | F23: =SUMIFS( Historique_Montant, Historique_Mois,F$7, Historique_Section,"Dépenses fixes - "&$A$20, Historique_Categorie,$A23, Historique_Enregistre,TRUE, Historique_Statut,"OK" ) -> 0 | G23: =SUMIFS( Historique_Montant, Historique_Mois,G$7, Historique_Section,"Dépenses fixes - "&$A$20, Historique_Categorie,$A23, Historique_Enregistre,TRUE, Historique_Statut,"OK" ) -> 0 | H23: =SUMIFS( Historique_Montant, Historique_Mois,H$7, Historique_Section,"Dépenses fixes - "&$A$20, Historique_Categorie,$A23, Historique_Enregistre,TRUE, Historique_Statut,"OK" ) -> 0 | I23: =SUMIFS( Historique_Montant, Historique_Mois,I$7, Historique_Section,"Dépenses fixes - "&$A$20, Historique_Categorie,$A23, Historique_Enregistre,TRUE, Historique_Statut,"OK" ) -> 0 | ... M23: =SUMIFS( Historique_Montant, Historique_Mois,M$7, Historique_Section,"Dépenses fixes - "&$A$20, Historique_Categorie,$A23, Historique_Enregistre,TRUE, Historique_Statut,"OK" ) -> 0 | N23: =SUM(B23:M23) -> 0
A24: Charge appartement | B24: =SUMIFS( Historique_Montant, Historique_Mois,B$7, Historique_Section,"Dépenses fixes - "&$A$20, Historique_Categorie,$A24, Historique_Enregistre,TRUE, Historique_Statut,"OK" ) -> 0 | C24: =SUMIFS( Historique_Montant, Historique_Mois,C$7, Historique_Section,"Dépenses fixes - "&$A$20, Historique_Categorie,$A24, Historique_Enregistre,TRUE, Historique_Statut,"OK" ) -> 0 | D24: =SUMIFS( Historique_Montant, Historique_Mois,D$7, Historique_Section,"Dépenses fixes - "&$A$20, Historique_Categorie,$A24, Historique_Enregistre,TRUE, Historique_Statut,"OK" ) -> 0 | E24: =SUMIFS( Historique_Montant, Historique_Mois,E$7, Historique_Section,"Dépenses fixes - "&$A$20, Historique_Categorie,$A24, Historique_Enregistre,TRUE, Historique_Statut,"OK" ) -> 0 | F24: =SUMIFS( Historique_Montant, Historique_Mois,F$7, Historique_Section,"Dépenses fixes - "&$A$20, Historique_Categorie,$A24, Historique_Enregistre,TRUE, Historique_Statut,"OK" ) -> 0 | G24: =SUMIFS( Historique_Montant, Historique_Mois,G$7, Historique_Section,"Dépenses fixes - "&$A$20, Historique_Categorie,$A24, Historique_Enregistre,TRUE, Historique_Statut,"OK" ) -> 0 | H24: =SUMIFS( Historique_Montant, Historique_Mois,H$7, Historique_Section,"Dépenses fixes - "&$A$20, Historique_Categorie,$A24, Historique_Enregistre,TRUE, Historique_Statut,"OK" ) -> 0 | I24: =SUMIFS( Historique_Montant, Historique_Mois,I$7, Historique_Section,"Dépenses fixes - "&$A$20, Historique_Categorie,$A24, Historique_Enregistre,TRUE, Historique_Statut,"OK" ) -> 0 | ... M24: =SUMIFS( Historique_Montant, Historique_Mois,M$7, Historique_Section,"Dépenses fixes - "&$A$20, Historique_Categorie,$A24, Historique_Enregistre,TRUE, Historique_Statut,"OK" ) -> 0 | N24: =SUM(B24:M24) -> 0
A25: Assurance habitation | B25: =SUMIFS( Historique_Montant, Historique_Mois,B$7, Historique_Section,"Dépenses fixes - "&$A$20, Historique_Categorie,$A25, Historique_Enregistre,TRUE, Historique_Statut,"OK" ) -> 0 | C25: =SUMIFS( Historique_Montant, Historique_Mois,C$7, Historique_Section,"Dépenses fixes - "&$A$20, Historique_Categorie,$A25, Historique_Enregistre,TRUE, Historique_Statut,"OK" ) -> 0 | D25: =SUMIFS( Historique_Montant, Historique_Mois,D$7, Historique_Section,"Dépenses fixes - "&$A$20, Historique_Categorie,$A25, Historique_Enregistre,TRUE, Historique_Statut,"OK" ) -> 0 | E25: =SUMIFS( Historique_Montant, Historique_Mois,E$7, Historique_Section,"Dépenses fixes - "&$A$20, Historique_Categorie,$A25, Historique_Enregistre,TRUE, Historique_Statut,"OK" ) -> 0 | F25: =SUMIFS( Historique_Montant, Historique_Mois,F$7, Historique_Section,"Dépenses fixes - "&$A$20, Historique_Categorie,$A25, Historique_Enregistre,TRUE, Historique_Statut,"OK" ) -> 0 | G25: =SUMIFS( Historique_Montant, Historique_Mois,G$7, Historique_Section,"Dépenses fixes - "&$A$20, Historique_Categorie,$A25, Historique_Enregistre,TRUE, Historique_Statut,"OK" ) -> 0 | H25: =SUMIFS( Historique_Montant, Historique_Mois,H$7, Historique_Section,"Dépenses fixes - "&$A$20, Historique_Categorie,$A25, Historique_Enregistre,TRUE, Historique_Statut,"OK" ) -> 0 | I25: =SUMIFS( Historique_Montant, Historique_Mois,I$7, Historique_Section,"Dépenses fixes - "&$A$20, Historique_Categorie,$A25, Historique_Enregistre,TRUE, Historique_Statut,"OK" ) -> 0 | ... M25: =SUMIFS( Historique_Montant, Historique_Mois,M$7, Historique_Section,"Dépenses fixes - "&$A$20, Historique_Categorie,$A25, Historique_Enregistre,TRUE, Historique_Statut,"OK" ) -> 0 | N25: =SUM(B25:M25) -> 0
B26: =SUMIFS( Historique_Montant, Historique_Mois,B$7, Historique_Section,"Dépenses fixes - "&$A$20, Historique_Categorie,$A26, Historique_Enregistre,TRUE, Historique_Statut,"OK" ) -> 0 | C26: =SUMIFS( Historique_Montant, Historique_Mois,C$7, Historique_Section,"Dépenses fixes - "&$A$20, Historique_Categorie,$A26, Historique_Enregistre,TRUE, Historique_Statut,"OK" ) -> 0 | D26: =SUMIFS( Historique_Montant, Historique_Mois,D$7, Historique_Section,"Dépenses fixes - "&$A$20, Historique_Categorie,$A26, Historique_Enregistre,TRUE, Historique_Statut,"OK" ) -> 0 | E26: =SUMIFS( Historique_Montant, Historique_Mois,E$7, Historique_Section,"Dépenses fixes - "&$A$20, Historique_Categorie,$A26, Historique_Enregistre,TRUE, Historique_Statut,"OK" ) -> 0 | F26: =SUMIFS( Historique_Montant, Historique_Mois,F$7, Historique_Section,"Dépenses fixes - "&$A$20, Historique_Categorie,$A26, Historique_Enregistre,TRUE, Historique_Statut,"OK" ) -> 0 | G26: =SUMIFS( Historique_Montant, Historique_Mois,G$7, Historique_Section,"Dépenses fixes - "&$A$20, Historique_Categorie,$A26, Historique_Enregistre,TRUE, Historique_Statut,"OK" ) -> 0 | H26: =SUMIFS( Historique_Montant, Historique_Mois,H$7, Historique_Section,"Dépenses fixes - "&$A$20, Historique_Categorie,$A26, Historique_Enregistre,TRUE, Historique_Statut,"OK" ) -> 0 | I26: =SUMIFS( Historique_Montant, Historique_Mois,I$7, Historique_Section,"Dépenses fixes - "&$A$20, Historique_Categorie,$A26, Historique_Enregistre,TRUE, Historique_Statut,"OK" ) -> 0 | ... M26: =SUMIFS( Historique_Montant, Historique_Mois,M$7, Historique_Section,"Dépenses fixes - "&$A$20, Historique_Categorie,$A26, Historique_Enregistre,TRUE, Historique_Statut,"OK" ) -> 0 | N26: =SUM(B26:M26) -> 0
B27: =SUMIFS( Historique_Montant, Historique_Mois,B$7, Historique_Section,"Dépenses fixes - "&$A$20, Historique_Categorie,$A27, Historique_Enregistre,TRUE, Historique_Statut,"OK" ) -> 0 | C27: =SUMIFS( Historique_Montant, Historique_Mois,C$7, Historique_Section,"Dépenses fixes - "&$A$20, Historique_Categorie,$A27, Historique_Enregistre,TRUE, Historique_Statut,"OK" ) -> 0 | D27: =SUMIFS( Historique_Montant, Historique_Mois,D$7, Historique_Section,"Dépenses fixes - "&$A$20, Historique_Categorie,$A27, Historique_Enregistre,TRUE, Historique_Statut,"OK" ) -> 0 | E27: =SUMIFS( Historique_Montant, Historique_Mois,E$7, Historique_Section,"Dépenses fixes - "&$A$20, Historique_Categorie,$A27, Historique_Enregistre,TRUE, Historique_Statut,"OK" ) -> 0 | F27: =SUMIFS( Historique_Montant, Historique_Mois,F$7, Historique_Section,"Dépenses fixes - "&$A$20, Historique_Categorie,$A27, Historique_Enregistre,TRUE, Historique_Statut,"OK" ) -> 0 | G27: =SUMIFS( Historique_Montant, Historique_Mois,G$7, Historique_Section,"Dépenses fixes - "&$A$20, Historique_Categorie,$A27, Historique_Enregistre,TRUE, Historique_Statut,"OK" ) -> 0 | H27: =SUMIFS( Historique_Montant, Historique_Mois,H$7, Historique_Section,"Dépenses fixes - "&$A$20, Historique_Categorie,$A27, Historique_Enregistre,TRUE, Historique_Statut,"OK" ) -> 0 | I27: =SUMIFS( Historique_Montant, Historique_Mois,I$7, Historique_Section,"Dépenses fixes - "&$A$20, Historique_Categorie,$A27, Historique_Enregistre,TRUE, Historique_Statut,"OK" ) -> 0 | ... M27: =SUMIFS( Historique_Montant, Historique_Mois,M$7, Historique_Section,"Dépenses fixes - "&$A$20, Historique_Categorie,$A27, Historique_Enregistre,TRUE, Historique_Statut,"OK" ) -> 0 | N27: =SUM(B27:M27) -> 0
A28: Autres (logement) | B28: =SUMIFS( Historique_Montant, Historique_Mois,B$7, Historique_Section,"Dépenses fixes - "&$A$20, Historique_Categorie,$A28, Historique_Enregistre,TRUE, Historique_Statut,"OK" ) -> 0 | C28: =SUMIFS( Historique_Montant, Historique_Mois,C$7, Historique_Section,"Dépenses fixes - "&$A$20, Historique_Categorie,$A28, Historique_Enregistre,TRUE, Historique_Statut,"OK" ) -> 0 | D28: =SUMIFS( Historique_Montant, Historique_Mois,D$7, Historique_Section,"Dépenses fixes - "&$A$20, Historique_Categorie,$A28, Historique_Enregistre,TRUE, Historique_Statut,"OK" ) -> 0 | E28: =SUMIFS( Historique_Montant, Historique_Mois,E$7, Historique_Section,"Dépenses fixes - "&$A$20, Historique_Categorie,$A28, Historique_Enregistre,TRUE, Historique_Statut,"OK" ) -> 0 | F28: =SUMIFS( Historique_Montant, Historique_Mois,F$7, Historique_Section,"Dépenses fixes - "&$A$20, Historique_Categorie,$A28, Historique_Enregistre,TRUE, Historique_Statut,"OK" ) -> 0 | G28: =SUMIFS( Historique_Montant, Historique_Mois,G$7, Historique_Section,"Dépenses fixes - "&$A$20, Historique_Categorie,$A28, Historique_Enregistre,TRUE, Historique_Statut,"OK" ) -> 0 | H28: =SUMIFS( Historique_Montant, Historique_Mois,H$7, Historique_Section,"Dépenses fixes - "&$A$20, Historique_Categorie,$A28, Historique_Enregistre,TRUE, Historique_Statut,"OK" ) -> 0 | I28: =SUMIFS( Historique_Montant, Historique_Mois,I$7, Historique_Section,"Dépenses fixes - "&$A$20, Historique_Categorie,$A28, Historique_Enregistre,TRUE, Historique_Statut,"OK" ) -> 0 | ... M28: =SUMIFS( Historique_Montant, Historique_Mois,M$7, Historique_Section,"Dépenses fixes - "&$A$20, Historique_Categorie,$A28, Historique_Enregistre,TRUE, Historique_Statut,"OK" ) -> 0 | N28: =SUM(B28:M28) -> 0
A29: Transport | B29: =SUM(B30:B34) -> 0 | C29: =SUM(C30:C34) -> 0 | D29: =SUM(D30:D34) -> 0 | E29: =SUM(E30:E34) -> 0 | F29: =SUM(F30:F34) -> 0 | G29: =SUM(G30:G34) -> 0 | H29: =SUM(H30:H34) -> 0 | I29: =SUM(I30:I34) -> 0 | ... M29: =SUM(M30:M34) -> 0 | N29: =SUM(B29:M29) -> 0
A30: Crédit auto | B30: =SUMIFS( Historique_Montant, Historique_Mois,B$7, Historique_Section,"Dépenses fixes - "&$A$29, Historique_Categorie,$A30, Historique_Enregistre,TRUE, Historique_Statut,"OK" ) -> 0 | C30: =SUMIFS( Historique_Montant, Historique_Mois,C$7, Historique_Section,"Dépenses fixes - "&$A$29, Historique_Categorie,$A30, Historique_Enregistre,TRUE, Historique_Statut,"OK" ) -> 0 | D30: =SUMIFS( Historique_Montant, Historique_Mois,D$7, Historique_Section,"Dépenses fixes - "&$A$29, Historique_Categorie,$A30, Historique_Enregistre,TRUE, Historique_Statut,"OK" ) -> 0 | E30: =SUMIFS( Historique_Montant, Historique_Mois,E$7, Historique_Section,"Dépenses fixes - "&$A$29, Historique_Categorie,$A30, Historique_Enregistre,TRUE, Historique_Statut,"OK" ) -> 0 | F30: =SUMIFS( Historique_Montant, Historique_Mois,F$7, Historique_Section,"Dépenses fixes - "&$A$29, Historique_Categorie,$A30, Historique_Enregistre,TRUE, Historique_Statut,"OK" ) -> 0 | G30: =SUMIFS( Historique_Montant, Historique_Mois,G$7, Historique_Section,"Dépenses fixes - "&$A$29, Historique_Categorie,$A30, Historique_Enregistre,TRUE, Historique_Statut,"OK" ) -> 0 | H30: =SUMIFS( Historique_Montant, Historique_Mois,H$7, Historique_Section,"Dépenses fixes - "&$A$29, Historique_Categorie,$A30, Historique_Enregistre,TRUE, Historique_Statut,"OK" ) -> 0 | I30: =SUMIFS( Historique_Montant, Historique_Mois,I$7, Historique_Section,"Dépenses fixes - "&$A$29, Historique_Categorie,$A30, Historique_Enregistre,TRUE, Historique_Statut,"OK" ) -> 0 | ... M30: =SUMIFS( Historique_Montant, Historique_Mois,M$7, Historique_Section,"Dépenses fixes - "&$A$29, Historique_Categorie,$A30, Historique_Enregistre,TRUE, Historique_Statut,"OK" ) -> 0 | N30: =SUM(B30:M30) -> 0
A31: Assurance auto | B31: =SUMIFS( Historique_Montant, Historique_Mois,B$7, Historique_Section,"Dépenses fixes - "&$A$29, Historique_Categorie,$A31, Historique_Enregistre,TRUE, Historique_Statut,"OK" ) -> 0 | C31: =SUMIFS( Historique_Montant, Historique_Mois,C$7, Historique_Section,"Dépenses fixes - "&$A$29, Historique_Categorie,$A31, Historique_Enregistre,TRUE, Historique_Statut,"OK" ) -> 0 | D31: =SUMIFS( Historique_Montant, Historique_Mois,D$7, Historique_Section,"Dépenses fixes - "&$A$29, Historique_Categorie,$A31, Historique_Enregistre,TRUE, Historique_Statut,"OK" ) -> 0 | E31: =SUMIFS( Historique_Montant, Historique_Mois,E$7, Historique_Section,"Dépenses fixes - "&$A$29, Historique_Categorie,$A31, Historique_Enregistre,TRUE, Historique_Statut,"OK" ) -> 0 | F31: =SUMIFS( Historique_Montant, Historique_Mois,F$7, Historique_Section,"Dépenses fixes - "&$A$29, Historique_Categorie,$A31, Historique_Enregistre,TRUE, Historique_Statut,"OK" ) -> 0 | G31: =SUMIFS( Historique_Montant, Historique_Mois,G$7, Historique_Section,"Dépenses fixes - "&$A$29, Historique_Categorie,$A31, Historique_Enregistre,TRUE, Historique_Statut,"OK" ) -> 0 | H31: =SUMIFS( Historique_Montant, Historique_Mois,H$7, Historique_Section,"Dépenses fixes - "&$A$29, Historique_Categorie,$A31, Historique_Enregistre,TRUE, Historique_Statut,"OK" ) -> 0 | I31: =SUMIFS( Historique_Montant, Historique_Mois,I$7, Historique_Section,"Dépenses fixes - "&$A$29, Historique_Categorie,$A31, Historique_Enregistre,TRUE, Historique_Statut,"OK" ) -> 0 | ... M31: =SUMIFS( Historique_Montant, Historique_Mois,M$7, Historique_Section,"Dépenses fixes - "&$A$29, Historique_Categorie,$A31, Historique_Enregistre,TRUE, Historique_Statut,"OK" ) -> 0 | N31: =SUM(B31:M31) -> 0
B32: =SUMIFS( Historique_Montant, Historique_Mois,B$7, Historique_Section,"Dépenses fixes - "&$A$29, Historique_Categorie,$A32, Historique_Enregistre,TRUE, Historique_Statut,"OK" ) -> 0 | C32: =SUMIFS( Historique_Montant, Historique_Mois,C$7, Historique_Section,"Dépenses fixes - "&$A$29, Historique_Categorie,$A32, Historique_Enregistre,TRUE, Historique_Statut,"OK" ) -> 0 | D32: =SUMIFS( Historique_Montant, Historique_Mois,D$7, Historique_Section,"Dépenses fixes - "&$A$29, Historique_Categorie,$A32, Historique_Enregistre,TRUE, Historique_Statut,"OK" ) -> 0 | E32: =SUMIFS( Historique_Montant, Historique_Mois,E$7, Historique_Section,"Dépenses fixes - "&$A$29, Historique_Categorie,$A32, Historique_Enregistre,TRUE, Historique_Statut,"OK" ) -> 0 | F32: =SUMIFS( Historique_Montant, Historique_Mois,F$7, Historique_Section,"Dépenses fixes - "&$A$29, Historique_Categorie,$A32, Historique_Enregistre,TRUE, Historique_Statut,"OK" ) -> 0 | G32: =SUMIFS( Historique_Montant, Historique_Mois,G$7, Historique_Section,"Dépenses fixes - "&$A$29, Historique_Categorie,$A32, Historique_Enregistre,TRUE, Historique_Statut,"OK" ) -> 0 | H32: =SUMIFS( Historique_Montant, Historique_Mois,H$7, Historique_Section,"Dépenses fixes - "&$A$29, Historique_Categorie,$A32, Historique_Enregistre,TRUE, Historique_Statut,"OK" ) -> 0 | I32: =SUMIFS( Historique_Montant, Historique_Mois,I$7, Historique_Section,"Dépenses fixes - "&$A$29, Historique_Categorie,$A32, Historique_Enregistre,TRUE, Historique_Statut,"OK" ) -> 0 | ... M32: =SUMIFS( Historique_Montant, Historique_Mois,M$7, Historique_Section,"Dépenses fixes - "&$A$29, Historique_Categorie,$A32, Historique_Enregistre,TRUE, Historique_Statut,"OK" ) -> 0 | N32: =SUM(B32:M32) -> 0
B33: =SUMIFS( Historique_Montant, Historique_Mois,B$7, Historique_Section,"Dépenses fixes - "&$A$29, Historique_Categorie,$A33, Historique_Enregistre,TRUE, Historique_Statut,"OK" ) -> 0 | C33: =SUMIFS( Historique_Montant, Historique_Mois,C$7, Historique_Section,"Dépenses fixes - "&$A$29, Historique_Categorie,$A33, Historique_Enregistre,TRUE, Historique_Statut,"OK" ) -> 0 | D33: =SUMIFS( Historique_Montant, Historique_Mois,D$7, Historique_Section,"Dépenses fixes - "&$A$29, Historique_Categorie,$A33, Historique_Enregistre,TRUE, Historique_Statut,"OK" ) -> 0 | E33: =SUMIFS( Historique_Montant, Historique_Mois,E$7, Historique_Section,"Dépenses fixes - "&$A$29, Historique_Categorie,$A33, Historique_Enregistre,TRUE, Historique_Statut,"OK" ) -> 0 | F33: =SUMIFS( Historique_Montant, Historique_Mois,F$7, Historique_Section,"Dépenses fixes - "&$A$29, Historique_Categorie,$A33, Historique_Enregistre,TRUE, Historique_Statut,"OK" ) -> 0 | G33: =SUMIFS( Historique_Montant, Historique_Mois,G$7, Historique_Section,"Dépenses fixes - "&$A$29, Historique_Categorie,$A33, Historique_Enregistre,TRUE, Historique_Statut,"OK" ) -> 0 | H33: =SUMIFS( Historique_Montant, Historique_Mois,H$7, Historique_Section,"Dépenses fixes - "&$A$29, Historique_Categorie,$A33, Historique_Enregistre,TRUE, Historique_Statut,"OK" ) -> 0 | I33: =SUMIFS( Historique_Montant, Historique_Mois,I$7, Historique_Section,"Dépenses fixes - "&$A$29, Historique_Categorie,$A33, Historique_Enregistre,TRUE, Historique_Statut,"OK" ) -> 0 | ... M33: =SUMIFS( Historique_Montant, Historique_Mois,M$7, Historique_Section,"Dépenses fixes - "&$A$29, Historique_Categorie,$A33, Historique_Enregistre,TRUE, Historique_Statut,"OK" ) -> 0 | N33: =SUM(B33:M33) -> 0
A34: Autres (transport) | B34: =SUMIFS( Historique_Montant, Historique_Mois,B$7, Historique_Section,"Dépenses fixes - "&$A$29, Historique_Categorie,$A34, Historique_Enregistre,TRUE, Historique_Statut,"OK" ) -> 0 | C34: =SUMIFS( Historique_Montant, Historique_Mois,C$7, Historique_Section,"Dépenses fixes - "&$A$29, Historique_Categorie,$A34, Historique_Enregistre,TRUE, Historique_Statut,"OK" ) -> 0 | D34: =SUMIFS( Historique_Montant, Historique_Mois,D$7, Historique_Section,"Dépenses fixes - "&$A$29, Historique_Categorie,$A34, Historique_Enregistre,TRUE, Historique_Statut,"OK" ) -> 0 | E34: =SUMIFS( Historique_Montant, Historique_Mois,E$7, Historique_Section,"Dépenses fixes - "&$A$29, Historique_Categorie,$A34, Historique_Enregistre,TRUE, Historique_Statut,"OK" ) -> 0 | F34: =SUMIFS( Historique_Montant, Historique_Mois,F$7, Historique_Section,"Dépenses fixes - "&$A$29, Historique_Categorie,$A34, Historique_Enregistre,TRUE, Historique_Statut,"OK" ) -> 0 | G34: =SUMIFS( Historique_Montant, Historique_Mois,G$7, Historique_Section,"Dépenses fixes - "&$A$29, Historique_Categorie,$A34, Historique_Enregistre,TRUE, Historique_Statut,"OK" ) -> 0 | H34: =SUMIFS( Historique_Montant, Historique_Mois,H$7, Historique_Section,"Dépenses fixes - "&$A$29, Historique_Categorie,$A34, Historique_Enregistre,TRUE, Historique_Statut,"OK" ) -> 0 | I34: =SUMIFS( Historique_Montant, Historique_Mois,I$7, Historique_Section,"Dépenses fixes - "&$A$29, Historique_Categorie,$A34, Historique_Enregistre,TRUE, Historique_Statut,"OK" ) -> 0 | ... M34: =SUMIFS( Historique_Montant, Historique_Mois,M$7, Historique_Section,"Dépenses fixes - "&$A$29, Historique_Categorie,$A34, Historique_Enregistre,TRUE, Historique_Statut,"OK" ) -> 0 | N34: =SUM(B34:M34) -> 0
A35: Abonnements | B35: =SUM(B36:B44) -> 0 | C35: =SUM(C36:C44) -> 0 | D35: =SUM(D36:D44) -> 0 | E35: =SUM(E36:E44) -> 0 | F35: =SUM(F36:F44) -> 0 | G35: =SUM(G36:G44) -> 0 | H35: =SUM(H36:H44) -> 0 | I35: =SUM(I36:I44) -> 0 | ... M35: =SUM(M36:M44) -> 0 | N35: =SUM(B35:M35) -> 0
A36: Mutuelle | B36: =SUMIFS( Historique_Montant, Historique_Mois,B$7, Historique_Section,"Dépenses fixes - "&$A$35, Historique_Categorie,$A36, Historique_Enregistre,TRUE, Historique_Statut,"OK" ) -> 0 | C36: =SUMIFS( Historique_Montant, Historique_Mois,C$7, Historique_Section,"Dépenses fixes - "&$A$35, Historique_Categorie,$A36, Historique_Enregistre,TRUE, Historique_Statut,"OK" ) -> 0 | D36: =SUMIFS( Historique_Montant, Historique_Mois,D$7, Historique_Section,"Dépenses fixes - "&$A$35, Historique_Categorie,$A36, Historique_Enregistre,TRUE, Historique_Statut,"OK" ) -> 0 | E36: =SUMIFS( Historique_Montant, Historique_Mois,E$7, Historique_Section,"Dépenses fixes - "&$A$35, Historique_Categorie,$A36, Historique_Enregistre,TRUE, Historique_Statut,"OK" ) -> 0 | F36: =SUMIFS( Historique_Montant, Historique_Mois,F$7, Historique_Section,"Dépenses fixes - "&$A$35, Historique_Categorie,$A36, Historique_Enregistre,TRUE, Historique_Statut,"OK" ) -> 0 | G36: =SUMIFS( Historique_Montant, Historique_Mois,G$7, Historique_Section,"Dépenses fixes - "&$A$35, Historique_Categorie,$A36, Historique_Enregistre,TRUE, Historique_Statut,"OK" ) -> 0 | H36: =SUMIFS( Historique_Montant, Historique_Mois,H$7, Historique_Section,"Dépenses fixes - "&$A$35, Historique_Categorie,$A36, Historique_Enregistre,TRUE, Historique_Statut,"OK" ) -> 0 | I36: =SUMIFS( Historique_Montant, Historique_Mois,I$7, Historique_Section,"Dépenses fixes - "&$A$35, Historique_Categorie,$A36, Historique_Enregistre,TRUE, Historique_Statut,"OK" ) -> 0 | ... M36: =SUMIFS( Historique_Montant, Historique_Mois,M$7, Historique_Section,"Dépenses fixes - "&$A$35, Historique_Categorie,$A36, Historique_Enregistre,TRUE, Historique_Statut,"OK" ) -> 0 | N36: =SUM(B36:M36) -> 0
A37: Box, internet, forfait(s) mobile(s) | B37: =SUMIFS( Historique_Montant, Historique_Mois,B$7, Historique_Section,"Dépenses fixes - "&$A$35, Historique_Categorie,$A37, Historique_Enregistre,TRUE, Historique_Statut,"OK" ) -> 0 | C37: =SUMIFS( Historique_Montant, Historique_Mois,C$7, Historique_Section,"Dépenses fixes - "&$A$35, Historique_Categorie,$A37, Historique_Enregistre,TRUE, Historique_Statut,"OK" ) -> 0 | D37: =SUMIFS( Historique_Montant, Historique_Mois,D$7, Historique_Section,"Dépenses fixes - "&$A$35, Historique_Categorie,$A37, Historique_Enregistre,TRUE, Historique_Statut,"OK" ) -> 0 | E37: =SUMIFS( Historique_Montant, Historique_Mois,E$7, Historique_Section,"Dépenses fixes - "&$A$35, Historique_Categorie,$A37, Historique_Enregistre,TRUE, Historique_Statut,"OK" ) -> 0 | F37: =SUMIFS( Historique_Montant, Historique_Mois,F$7, Historique_Section,"Dépenses fixes - "&$A$35, Historique_Categorie,$A37, Historique_Enregistre,TRUE, Historique_Statut,"OK" ) -> 0 | G37: =SUMIFS( Historique_Montant, Historique_Mois,G$7, Historique_Section,"Dépenses fixes - "&$A$35, Historique_Categorie,$A37, Historique_Enregistre,TRUE, Historique_Statut,"OK" ) -> 0 | H37: =SUMIFS( Historique_Montant, Historique_Mois,H$7, Historique_Section,"Dépenses fixes - "&$A$35, Historique_Categorie,$A37, Historique_Enregistre,TRUE, Historique_Statut,"OK" ) -> 0 | I37: =SUMIFS( Historique_Montant, Historique_Mois,I$7, Historique_Section,"Dépenses fixes - "&$A$35, Historique_Categorie,$A37, Historique_Enregistre,TRUE, Historique_Statut,"OK" ) -> 0 | ... M37: =SUMIFS( Historique_Montant, Historique_Mois,M$7, Historique_Section,"Dépenses fixes - "&$A$35, Historique_Categorie,$A37, Historique_Enregistre,TRUE, Historique_Statut,"OK" ) -> 0 | N37: =SUM(B37:M37) -> 0
A38: Vidéo (Netflix, Canal+…) | B38: =SUMIFS( Historique_Montant, Historique_Mois,B$7, Historique_Section,"Dépenses fixes - "&$A$35, Historique_Categorie,$A38, Historique_Enregistre,TRUE, Historique_Statut,"OK" ) -> 0 | C38: =SUMIFS( Historique_Montant, Historique_Mois,C$7, Historique_Section,"Dépenses fixes - "&$A$35, Historique_Categorie,$A38, Historique_Enregistre,TRUE, Historique_Statut,"OK" ) -> 0 | D38: =SUMIFS( Historique_Montant, Historique_Mois,D$7, Historique_Section,"Dépenses fixes - "&$A$35, Historique_Categorie,$A38, Historique_Enregistre,TRUE, Historique_Statut,"OK" ) -> 0 | E38: =SUMIFS( Historique_Montant, Historique_Mois,E$7, Historique_Section,"Dépenses fixes - "&$A$35, Historique_Categorie,$A38, Historique_Enregistre,TRUE, Historique_Statut,"OK" ) -> 0 | F38: =SUMIFS( Historique_Montant, Historique_Mois,F$7, Historique_Section,"Dépenses fixes - "&$A$35, Historique_Categorie,$A38, Historique_Enregistre,TRUE, Historique_Statut,"OK" ) -> 0 | G38: =SUMIFS( Historique_Montant, Historique_Mois,G$7, Historique_Section,"Dépenses fixes - "&$A$35, Historique_Categorie,$A38, Historique_Enregistre,TRUE, Historique_Statut,"OK" ) -> 0 | H38: =SUMIFS( Historique_Montant, Historique_Mois,H$7, Historique_Section,"Dépenses fixes - "&$A$35, Historique_Categorie,$A38, Historique_Enregistre,TRUE, Historique_Statut,"OK" ) -> 0 | I38: =SUMIFS( Historique_Montant, Historique_Mois,I$7, Historique_Section,"Dépenses fixes - "&$A$35, Historique_Categorie,$A38, Historique_Enregistre,TRUE, Historique_Statut,"OK" ) -> 0 | ... M38: =SUMIFS( Historique_Montant, Historique_Mois,M$7, Historique_Section,"Dépenses fixes - "&$A$35, Historique_Categorie,$A38, Historique_Enregistre,TRUE, Historique_Statut,"OK" ) -> 0 | N38: =SUM(B38:M38) -> 0
A39: Musique (Spotify…) | B39: =SUMIFS( Historique_Montant, Historique_Mois,B$7, Historique_Section,"Dépenses fixes - "&$A$35, Historique_Categorie,$A39, Historique_Enregistre,TRUE, Historique_Statut,"OK" ) -> 0 | C39: =SUMIFS( Historique_Montant, Historique_Mois,C$7, Historique_Section,"Dépenses fixes - "&$A$35, Historique_Categorie,$A39, Historique_Enregistre,TRUE, Historique_Statut,"OK" ) -> 0 | D39: =SUMIFS( Historique_Montant, Historique_Mois,D$7, Historique_Section,"Dépenses fixes - "&$A$35, Historique_Categorie,$A39, Historique_Enregistre,TRUE, Historique_Statut,"OK" ) -> 0 | E39: =SUMIFS( Historique_Montant, Historique_Mois,E$7, Historique_Section,"Dépenses fixes - "&$A$35, Historique_Categorie,$A39, Historique_Enregistre,TRUE, Historique_Statut,"OK" ) -> 0 | F39: =SUMIFS( Historique_Montant, Historique_Mois,F$7, Historique_Section,"Dépenses fixes - "&$A$35, Historique_Categorie,$A39, Historique_Enregistre,TRUE, Historique_Statut,"OK" ) -> 0 | G39: =SUMIFS( Historique_Montant, Historique_Mois,G$7, Historique_Section,"Dépenses fixes - "&$A$35, Historique_Categorie,$A39, Historique_Enregistre,TRUE, Historique_Statut,"OK" ) -> 0 | H39: =SUMIFS( Historique_Montant, Historique_Mois,H$7, Historique_Section,"Dépenses fixes - "&$A$35, Historique_Categorie,$A39, Historique_Enregistre,TRUE, Historique_Statut,"OK" ) -> 0 | I39: =SUMIFS( Historique_Montant, Historique_Mois,I$7, Historique_Section,"Dépenses fixes - "&$A$35, Historique_Categorie,$A39, Historique_Enregistre,TRUE, Historique_Statut,"OK" ) -> 0 | ... M39: =SUMIFS( Historique_Montant, Historique_Mois,M$7, Historique_Section,"Dépenses fixes - "&$A$35, Historique_Categorie,$A39, Historique_Enregistre,TRUE, Historique_Statut,"OK" ) -> 0 | N39: =SUM(B39:M39) -> 0
A40: Shopping (Amazon Prime…) | B40: =SUMIFS( Historique_Montant, Historique_Mois,B$7, Historique_Section,"Dépenses fixes - "&$A$35, Historique_Categorie,$A40, Historique_Enregistre,TRUE, Historique_Statut,"OK" ) -> 0 | C40: =SUMIFS( Historique_Montant, Historique_Mois,C$7, Historique_Section,"Dépenses fixes - "&$A$35, Historique_Categorie,$A40, Historique_Enregistre,TRUE, Historique_Statut,"OK" ) -> 0 | D40: =SUMIFS( Historique_Montant, Historique_Mois,D$7, Historique_Section,"Dépenses fixes - "&$A$35, Historique_Categorie,$A40, Historique_Enregistre,TRUE, Historique_Statut,"OK" ) -> 0 | E40: =SUMIFS( Historique_Montant, Historique_Mois,E$7, Historique_Section,"Dépenses fixes - "&$A$35, Historique_Categorie,$A40, Historique_Enregistre,TRUE, Historique_Statut,"OK" ) -> 0 | F40: =SUMIFS( Historique_Montant, Historique_Mois,F$7, Historique_Section,"Dépenses fixes - "&$A$35, Historique_Categorie,$A40, Historique_Enregistre,TRUE, Historique_Statut,"OK" ) -> 0 | G40: =SUMIFS( Historique_Montant, Historique_Mois,G$7, Historique_Section,"Dépenses fixes - "&$A$35, Historique_Categorie,$A40, Historique_Enregistre,TRUE, Historique_Statut,"OK" ) -> 0 | H40: =SUMIFS( Historique_Montant, Historique_Mois,H$7, Historique_Section,"Dépenses fixes - "&$A$35, Historique_Categorie,$A40, Historique_Enregistre,TRUE, Historique_Statut,"OK" ) -> 0 | I40: =SUMIFS( Historique_Montant, Historique_Mois,I$7, Historique_Section,"Dépenses fixes - "&$A$35, Historique_Categorie,$A40, Historique_Enregistre,TRUE, Historique_Statut,"OK" ) -> 0 | ... M40: =SUMIFS( Historique_Montant, Historique_Mois,M$7, Historique_Section,"Dépenses fixes - "&$A$35, Historique_Categorie,$A40, Historique_Enregistre,TRUE, Historique_Statut,"OK" ) -> 0 | N40: =SUM(B40:M40) -> 0
A41: Sport (salle, club…) | B41: =SUMIFS( Historique_Montant, Historique_Mois,B$7, Historique_Section,"Dépenses fixes - "&$A$35, Historique_Categorie,$A41, Historique_Enregistre,TRUE, Historique_Statut,"OK" ) -> 0 | C41: =SUMIFS( Historique_Montant, Historique_Mois,C$7, Historique_Section,"Dépenses fixes - "&$A$35, Historique_Categorie,$A41, Historique_Enregistre,TRUE, Historique_Statut,"OK" ) -> 0 | D41: =SUMIFS( Historique_Montant, Historique_Mois,D$7, Historique_Section,"Dépenses fixes - "&$A$35, Historique_Categorie,$A41, Historique_Enregistre,TRUE, Historique_Statut,"OK" ) -> 0 | E41: =SUMIFS( Historique_Montant, Historique_Mois,E$7, Historique_Section,"Dépenses fixes - "&$A$35, Historique_Categorie,$A41, Historique_Enregistre,TRUE, Historique_Statut,"OK" ) -> 0 | F41: =SUMIFS( Historique_Montant, Historique_Mois,F$7, Historique_Section,"Dépenses fixes - "&$A$35, Historique_Categorie,$A41, Historique_Enregistre,TRUE, Historique_Statut,"OK" ) -> 0 | G41: =SUMIFS( Historique_Montant, Historique_Mois,G$7, Historique_Section,"Dépenses fixes - "&$A$35, Historique_Categorie,$A41, Historique_Enregistre,TRUE, Historique_Statut,"OK" ) -> 0 | H41: =SUMIFS( Historique_Montant, Historique_Mois,H$7, Historique_Section,"Dépenses fixes - "&$A$35, Historique_Categorie,$A41, Historique_Enregistre,TRUE, Historique_Statut,"OK" ) -> 0 | I41: =SUMIFS( Historique_Montant, Historique_Mois,I$7, Historique_Section,"Dépenses fixes - "&$A$35, Historique_Categorie,$A41, Historique_Enregistre,TRUE, Historique_Statut,"OK" ) -> 0 | ... M41: =SUMIFS( Historique_Montant, Historique_Mois,M$7, Historique_Section,"Dépenses fixes - "&$A$35, Historique_Categorie,$A41, Historique_Enregistre,TRUE, Historique_Statut,"OK" ) -> 0 | N41: =SUM(B41:M41) -> 0
A42: Frais bancaire | B42: =SUMIFS( Historique_Montant, Historique_Mois,B$7, Historique_Section,"Dépenses fixes - "&$A$35, Historique_Categorie,$A42, Historique_Enregistre,TRUE, Historique_Statut,"OK" ) -> 0 | C42: =SUMIFS( Historique_Montant, Historique_Mois,C$7, Historique_Section,"Dépenses fixes - "&$A$35, Historique_Categorie,$A42, Historique_Enregistre,TRUE, Historique_Statut,"OK" ) -> 0 | D42: =SUMIFS( Historique_Montant, Historique_Mois,D$7, Historique_Section,"Dépenses fixes - "&$A$35, Historique_Categorie,$A42, Historique_Enregistre,TRUE, Historique_Statut,"OK" ) -> 0 | E42: =SUMIFS( Historique_Montant, Historique_Mois,E$7, Historique_Section,"Dépenses fixes - "&$A$35, Historique_Categorie,$A42, Historique_Enregistre,TRUE, Historique_Statut,"OK" ) -> 0 | F42: =SUMIFS( Historique_Montant, Historique_Mois,F$7, Historique_Section,"Dépenses fixes - "&$A$35, Historique_Categorie,$A42, Historique_Enregistre,TRUE, Historique_Statut,"OK" ) -> 0 | G42: =SUMIFS( Historique_Montant, Historique_Mois,G$7, Historique_Section,"Dépenses fixes - "&$A$35, Historique_Categorie,$A42, Historique_Enregistre,TRUE, Historique_Statut,"OK" ) -> 0 | H42: =SUMIFS( Historique_Montant, Historique_Mois,H$7, Historique_Section,"Dépenses fixes - "&$A$35, Historique_Categorie,$A42, Historique_Enregistre,TRUE, Historique_Statut,"OK" ) -> 0 | I42: =SUMIFS( Historique_Montant, Historique_Mois,I$7, Historique_Section,"Dépenses fixes - "&$A$35, Historique_Categorie,$A42, Historique_Enregistre,TRUE, Historique_Statut,"OK" ) -> 0 | ... M42: =SUMIFS( Historique_Montant, Historique_Mois,M$7, Historique_Section,"Dépenses fixes - "&$A$35, Historique_Categorie,$A42, Historique_Enregistre,TRUE, Historique_Statut,"OK" ) -> 0 | N42: =SUM(B42:M42) -> 0
B43: =SUMIFS( Historique_Montant, Historique_Mois,B$7, Historique_Section,"Dépenses fixes - "&$A$35, Historique_Categorie,$A43, Historique_Enregistre,TRUE, Historique_Statut,"OK" ) -> 0 | C43: =SUMIFS( Historique_Montant, Historique_Mois,C$7, Historique_Section,"Dépenses fixes - "&$A$35, Historique_Categorie,$A43, Historique_Enregistre,TRUE, Historique_Statut,"OK" ) -> 0 | D43: =SUMIFS( Historique_Montant, Historique_Mois,D$7, Historique_Section,"Dépenses fixes - "&$A$35, Historique_Categorie,$A43, Historique_Enregistre,TRUE, Historique_Statut,"OK" ) -> 0 | E43: =SUMIFS( Historique_Montant, Historique_Mois,E$7, Historique_Section,"Dépenses fixes - "&$A$35, Historique_Categorie,$A43, Historique_Enregistre,TRUE, Historique_Statut,"OK" ) -> 0 | F43: =SUMIFS( Historique_Montant, Historique_Mois,F$7, Historique_Section,"Dépenses fixes - "&$A$35, Historique_Categorie,$A43, Historique_Enregistre,TRUE, Historique_Statut,"OK" ) -> 0 | G43: =SUMIFS( Historique_Montant, Historique_Mois,G$7, Historique_Section,"Dépenses fixes - "&$A$35, Historique_Categorie,$A43, Historique_Enregistre,TRUE, Historique_Statut,"OK" ) -> 0 | H43: =SUMIFS( Historique_Montant, Historique_Mois,H$7, Historique_Section,"Dépenses fixes - "&$A$35, Historique_Categorie,$A43, Historique_Enregistre,TRUE, Historique_Statut,"OK" ) -> 0 | I43: =SUMIFS( Historique_Montant, Historique_Mois,I$7, Historique_Section,"Dépenses fixes - "&$A$35, Historique_Categorie,$A43, Historique_Enregistre,TRUE, Historique_Statut,"OK" ) -> 0 | ... M43: =SUMIFS( Historique_Montant, Historique_Mois,M$7, Historique_Section,"Dépenses fixes - "&$A$35, Historique_Categorie,$A43, Historique_Enregistre,TRUE, Historique_Statut,"OK" ) -> 0 | N43: =SUM(B43:M43) -> 0
A44: Autres (abonnements) | B44: =SUMIFS( Historique_Montant, Historique_Mois,B$7, Historique_Section,"Dépenses fixes - "&$A$35, Historique_Categorie,$A44, Historique_Enregistre,TRUE, Historique_Statut,"OK" ) -> 0 | C44: =SUMIFS( Historique_Montant, Historique_Mois,C$7, Historique_Section,"Dépenses fixes - "&$A$35, Historique_Categorie,$A44, Historique_Enregistre,TRUE, Historique_Statut,"OK" ) -> 0 | D44: =SUMIFS( Historique_Montant, Historique_Mois,D$7, Historique_Section,"Dépenses fixes - "&$A$35, Historique_Categorie,$A44, Historique_Enregistre,TRUE, Historique_Statut,"OK" ) -> 0 | E44: =SUMIFS( Historique_Montant, Historique_Mois,E$7, Historique_Section,"Dépenses fixes - "&$A$35, Historique_Categorie,$A44, Historique_Enregistre,TRUE, Historique_Statut,"OK" ) -> 0 | F44: =SUMIFS( Historique_Montant, Historique_Mois,F$7, Historique_Section,"Dépenses fixes - "&$A$35, Historique_Categorie,$A44, Historique_Enregistre,TRUE, Historique_Statut,"OK" ) -> 0 | G44: =SUMIFS( Historique_Montant, Historique_Mois,G$7, Historique_Section,"Dépenses fixes - "&$A$35, Historique_Categorie,$A44, Historique_Enregistre,TRUE, Historique_Statut,"OK" ) -> 0 | H44: =SUMIFS( Historique_Montant, Historique_Mois,H$7, Historique_Section,"Dépenses fixes - "&$A$35, Historique_Categorie,$A44, Historique_Enregistre,TRUE, Historique_Statut,"OK" ) -> 0 | I44: =SUMIFS( Historique_Montant, Historique_Mois,I$7, Historique_Section,"Dépenses fixes - "&$A$35, Historique_Categorie,$A44, Historique_Enregistre,TRUE, Historique_Statut,"OK" ) -> 0 | ... M44: =SUMIFS( Historique_Montant, Historique_Mois,M$7, Historique_Section,"Dépenses fixes - "&$A$35, Historique_Categorie,$A44, Historique_Enregistre,TRUE, Historique_Statut,"OK" ) -> 0 | N44: =SUM(B44:M44) -> 0
A45: Epargne et investissement | B45: =SUM(B46:B53) -> 0 | C45: =SUM(C46:C53) -> 0 | D45: =SUM(D46:D53) -> 0 | E45: =SUM(E46:E53) -> 0 | F45: =SUM(F46:F53) -> 0 | G45: =SUM(G46:G53) -> 0 | H45: =SUM(H46:H53) -> 0 | I45: =SUM(I46:I53) -> 0 | ... M45: =SUM(M46:M53) -> 0 | N45: =SUM(B45:M45) -> 0
...

Sheet Historique
A1: Historique du budget - Journal de saisie — classé par mois. ☑ = enregistré -
A5: Mois | B5: Section | C5: Catégorie | D5: Statut | E5: Montant | F5: Enregistré | G5: Date | H5: Commentaire
D6: =IF(OR(Historique!$B6="",Historique!$C6=""),"",IF(IFERROR(COUNTIF(INDEX(Données!$E$2:$Z$100,0,MATCH(Historique!$B6,Données!$E$1:$Z$1,0)),Historique!$C6),0)>0,"OK","⚠ ERREUR"))
A7: Janvier | B7: Revenus | C7: Salaire et retraite | D7: =IF(OR(Historique!$B7="",Historique!$C7=""),"",IF(IFERROR(COUNTIF(INDEX(Données!$E$2:$Z$100,0,MATCH(Historique!$B7,Données!$E$1:$Z$1,0)),Historique!$C7),0)>0,"OK","⚠ ERREUR")) -> OK | E7: 1800 | F7: TRUE | G7: 46023 | H7: Exemple1 | J7: =IF(B7="","",_xlfn.XLOOKUP(B7,Données!$P$2:$P$11,Données!$Q$2:$Q$11,"")) -> Cat_Revenus
A8: Janvier | B8: Dépenses fixes - Transport | C8: Crédit auto | D8: =IF(OR(Historique!$B8="",Historique!$C8=""),"",IF(IFERROR(COUNTIF(INDEX(Données!$E$2:$Z$100,0,MATCH(Historique!$B8,Données!$E$1:$Z$1,0)),Historique!$C8),0)>0,"OK","⚠ ERREUR")) -> OK | E8: 250 | F8: FALSE | G8: 46023 | H8: Exemple2 | J8: =IF(B8="","",_xlfn.XLOOKUP(B8,Données!$P$2:$P$11,Données!$Q$2:$Q$11,"")) -> Cat_DF_Transport
D9: =IF(OR(Historique!$B9="",Historique!$C9=""),"",IF(IFERROR(COUNTIF(INDEX(Données!$E$2:$Z$100,0,MATCH(Historique!$B9,Données!$E$1:$Z$1,0)),Historique!$C9),0)>0,"OK","⚠ ERREUR")) | F9: TRUE | J9: =IF(B9="","",_xlfn.XLOOKUP(B9,Données!$P$2:$P$11,Données!$Q$2:$Q$11,""))
D10: =IF(OR(Historique!$B10="",Historique!$C10=""),"",IF(IFERROR(COUNTIF(INDEX(Données!$E$2:$Z$100,0,MATCH(Historique!$B10,Données!$E$1:$Z$1,0)),Historique!$C10),0)>0,"OK","⚠ ERREUR")) | F10: FALSE | J10: =IF(B10="","",_xlfn.XLOOKUP(B10,Données!$P$2:$P$11,Données!$Q$2:$Q$11,""))
D11: =IF(OR(Historique!$B11="",Historique!$C11=""),"",IF(IFERROR(COUNTIF(INDEX(Données!$E$2:$Z$100,0,MATCH(Historique!$B11,Données!$E$1:$Z$1,0)),Historique!$C11),0)>0,"OK","⚠ ERREUR")) | F11: FALSE | J11: =IF(B11="","",_xlfn.XLOOKUP(B11,Données!$P$2:$P$11,Données!$Q$2:$Q$11,""))
D12: =IF(OR(Historique!$B12="",Historique!$C12=""),"",IF(IFERROR(COUNTIF(INDEX(Données!$E$2:$Z$100,0,MATCH(Historique!$B12,Données!$E$1:$Z$1,0)),Historique!$C12),0)>0,"OK","⚠ ERREUR")) | F12: FALSE | J12: =IF(B12="","",_xlfn.XLOOKUP(B12,Données!$P$2:$P$11,Données!$Q$2:$Q$11,""))
D13: =IF(OR(Historique!$B13="",Historique!$C13=""),"",IF(IFERROR(COUNTIF(INDEX(Données!$E$2:$Z$100,0,MATCH(Historique!$B13,Données!$E$1:$Z$1,0)),Historique!$C13),0)>0,"OK","⚠ ERREUR")) | F13: FALSE | J13: =IF(B13="","",_xlfn.XLOOKUP(B13,Données!$P$2:$P$11,Données!$Q$2:$Q$11,""))
D14: =IF(OR(Historique!$B14="",Historique!$C14=""),"",IF(IFERROR(COUNTIF(INDEX(Données!$E$2:$Z$100,0,MATCH(Historique!$B14,Données!$E$1:$Z$1,0)),Historique!$C14),0)>0,"OK","⚠ ERREUR")) | F14: FALSE | J14: =IF(B14="","",_xlfn.XLOOKUP(B14,Données!$P$2:$P$11,Données!$Q$2:$Q$11,""))
D15: =IF(OR(Historique!$B15="",Historique!$C15=""),"",IF(IFERROR(COUNTIF(INDEX(Données!$E$2:$Z$100,0,MATCH(Historique!$B15,Données!$E$1:$Z$1,0)),Historique!$C15),0)>0,"OK","⚠ ERREUR")) | F15: FALSE | J15: =IF(B15="","",_xlfn.XLOOKUP(B15,Données!$P$2:$P$11,Données!$Q$2:$Q$11,""))
D16: =IF(OR(Historique!$B16="",Historique!$C16=""),"",IF(IFERROR(COUNTIF(INDEX(Données!$E$2:$Z$100,0,MATCH(Historique!$B16,Données!$E$1:$Z$1,0)),Historique!$C16),0)>0,"OK","⚠ ERREUR")) | F16: FALSE | J16: =IF(B16="","",_xlfn.XLOOKUP(B16,Données!$P$2:$P$11,Données!$Q$2:$Q$11,""))
D17: =IF(OR(Historique!$B17="",Historique!$C17=""),"",IF(IFERROR(COUNTIF(INDEX(Données!$E$2:$Z$100,0,MATCH(Historique!$B17,Données!$E$1:$Z$1,0)),Historique!$C17),0)>0,"OK","⚠ ERREUR")) | F17: FALSE | J17: =IF(B17="","",_xlfn.XLOOKUP(B17,Données!$P$2:$P$11,Données!$Q$2:$Q$11,""))
D18: =IF(OR(Historique!$B18="",Historique!$C18=""),"",IF(IFERROR(COUNTIF(INDEX(Données!$E$2:$Z$100,0,MATCH(Historique!$B18,Données!$E$1:$Z$1,0)),Historique!$C18),0)>0,"OK","⚠ ERREUR")) | F18: FALSE | J18: =IF(B18="","",_xlfn.XLOOKUP(B18,Données!$P$2:$P$11,Données!$Q$2:$Q$11,""))
D19: =IF(OR(Historique!$B19="",Historique!$C19=""),"",IF(IFERROR(COUNTIF(INDEX(Données!$E$2:$Z$100,0,MATCH(Historique!$B19,Données!$E$1:$Z$1,0)),Historique!$C19),0)>0,"OK","⚠ ERREUR")) | F19: FALSE | J19: =IF(B19="","",_xlfn.XLOOKUP(B19,Données!$P$2:$P$11,Données!$Q$2:$Q$11,""))
D20: =IF(OR(Historique!$B20="",Historique!$C20=""),"",IF(IFERROR(COUNTIF(INDEX(Données!$E$2:$Z$100,0,MATCH(Historique!$B20,Données!$E$1:$Z$1,0)),Historique!$C20),0)>0,"OK","⚠ ERREUR")) | F20: FALSE | J20: =IF(B20="","",_xlfn.XLOOKUP(B20,Données!$P$2:$P$11,Données!$Q$2:$Q$11,""))
... D5006: =IF(OR(Historique!$B5006="",Historique!$C5006=""),"",IF(IFERROR(COUNTIF(INDEX(Données!$E$2:$Z$100,0,MATCH(Historique!$B5006,Données!$E$1:$Z$1,0)),Historique!$C5006),0)>0,"OK","⚠ ERREUR")) | F5006: FALSE | J5006: =IF(B5006="","",_xlfn.XLOOKUP(B5006,Données!$P$2:$P$11,Données!$Q$2:$Q$11,""))
D5007: =IF(OR(Historique!$B5007="",Historique!$C5007=""),"",IF(IFERROR(COUNTIF(INDEX(Données!$E$2:$Z$100,0,MATCH(Historique!$B5007,Données!$E$1:$Z$1,0)),Historique!$C5007),0)>0,"OK","⚠ ERREUR")) | F5007: FALSE

Sheet Analyse
A1: Analyse du budget - Vue synthétique des revenus, dépenses et du reste à vivre -
A5: MOIS ANALYSÉ | B5: Octobre
A7: REVENUS | E7: DÉPENSES FIXES | H7: DÉPENSES VARIABLES | L7: RESTE
